Workbook

Sheet Лист1
A1: javax.faces.component.UIPanel@7d089a51 | B1: State | C1: Covered Entity Type | D1: Individuals Affected | E1: Breach Submission Date | F1: Type of Breach | G1: Location of Breached Information | H1: javax.faces.component.UIPanel@4427ba5 | I1: Web Description
A2: Integrative Emergency Services, LLC | B2: TX | C2: Business Associate | D2: 2009 | E2: 08/14/2026 | F2: Hacking/IT Incident | G2: Email | H2: Yes | I2: 14
A3: Mountain Rheumatology Professional, LLC | B3: CO | C3: Healthcare Provider | D3: 5378 | E3: 08/14/2026 | F3: Hacking/IT Incident | G3: Network Server | H3: No | I3: 14
A4: Baylor Genetics | B4: TX | C4: Healthcare Provider | D4: 2810878 | E4: 08/14/2026 | F4: Hacking/IT Incident | G4: Network Server | H4: No | I4: 14
A5: Deseye, PLLC d/b/a Princeton Family Eye Care | B5: TX | C5: Healthcare Provider | D5: 1050 | E5: 08/07/2026 | F5: Hacking/IT Incident | G5: Email | H5: No | I5: 14
A6: Indico Data Solutions, Inc. | B6: MA | C6: Business Associate | D6: 4840 | E6: 08/07/2026 | F6: Hacking/IT Incident | G6: Network Server | H6: Yes | I6: 14
A7: Horizon Eye Care Laser & Eye Surgery Center | B7: NJ | C7: Healthcare Provider | D7: 501 | E7: 08/07/2026 | F7: Hacking/IT Incident | G7: Network Server | H7: No | I7: 14
A8: NFI North, Inc. | B8: NH | C8: Healthcare Provider | D8: 49540 | E8: 08/05/2026 | F8: Hacking/IT Incident | G8: Network Server | H8: No | I8: 14
A9: PAMCAH-UA Local 675 Health and Welfare Fund | B9: HI | C9: Health Plan | D9: 8319 | E9: 08/03/2026 | F9: Hacking/IT Incident | G9: Email | H9: No | I9: 14
A10: Interim HealthCare of Oklahoma City, Inc. | B10: OK | C10: Healthcare Provider | D10: 500 | E10: 07/31/2026 | F10: Hacking/IT Incident | G10: Email, Network Server | H10: No | I10: 14
A11: Manning Regional Healthcare Center | B11: IA | C11: Healthcare Provider | D11: 746 | E11: 07/31/2026 | F11: Hacking/IT Incident | G11: Email | H11: No | I11: 14
A12: Aesto, LLC | B12: AL | C12: Business Associate | D12: 9540683 | E12: 07/31/2026 | F12: Hacking/IT Incident | G12: Network Server | H12: Yes | I12: 14
A13: Monongalia County General Hospital Company | B13: WV | C13: Healthcare Provider | D13: 2173 | E13: 07/31/2026 | F13: Hacking/IT Incident | G13: Email | H13: No | I13: 14
... A1053: La Perouse, LLC | B1053: NV | C1053: Business Associate | D1053: 501 | E1053: 09/02/2025 | F1053: Hacking/IT Incident | G1053: Network Server | H1053: Yes | I1053: 14

Sheet Лист2
A1: Неделя | B1: Кол-во инцидентов | C1: Прогнозируемое значени | D1: Относительная ошибка | E1: Абсолютная ошибка
A2: 45537 | B2: 1
A3: 45544 | B3: 2
A4: 45551 | B4: 3
A5: 45565 | B5: 1
A6: 45572 | B6: 5
A7: 45579 | B7: 5
A8: 45586 | B8: 2
A9: 45593 | B9: 2
A10: 45600 | B10: 3
A11: 45607 | B11: 5
A12: 45614 | B12: 4
A13: 45621 | B13: 4
... A100: 46244 | B100: 5

Sheet Фостер Стюарт
A1: t | B1: Инциденты y_t | C1: Максимум до t | D1: Минимум до t | E1: u_t | F1: l_t | G1: d_t = u_t-l_t | H1: 1/t | M1: a | N1: b | P1: Неделя t | Q1: Дата недели | R1: Факт (только 1–60) | S1: Свободный член a | T1: Вклад наклона b·t | U1: Линия тренда a+b·t | V1: Период
A2: 2 | B2: =Лист2!B3 -> 2 | C2: =MAX(Лист2!$B$2:B2) -> 1 | D2: =MIN(Лист2!$B$2:B2) -> 1 | E2: =IF(B2>C2,1,0) -> 1 | F2: =IF(B2<D2,1,0) -> 0 | G2: =E2-F2 -> 1 | H2: =1/A2 -> 0.5 | I2: =A2+Лист2!B2 -> 3 | J2: =Лист2!B2^2+A2^2 -> 5 | K2: =B2+Лист2!B2 -> 3 | L2: =A2*B2+'Фостер Стюарт'!B2 -> 6 | M2: =1406/885 -> 1.5887006 | N2: =2878/17995 -> 0.15993331 | P2: 1 | Q2: =Лист2!A2 -> 45537 | R2: =Лист2!B2 -> 1 | S2: =$M$2 -> 1.5887006 | T2: =$N$2*P2 -> 0.15993331 | U2: =S2+T2 -> 1.7486339 | V2: =IF(P2<=60,"Наблюдение","Упреждение") -> Наблюдение
A3: 3 | B3: =Лист2!B4 -> 3 | C3: =MAX(Лист2!$B$2:B3) -> 2 | D3: =MIN(Лист2!$B$2:B3) -> 1 | E3: =IF(B3>C3,1,0) -> 1 | F3: =IF(B3<D3,1,0) -> 0 | G3: =E3-F3 -> 1 | H3: =1/A3 -> 0.33333333 | I3: =A3+I2 -> 6 | J3: =A3^2+J2 -> 14 | K3: =B3+K2 -> 6 | L3: =A3*B3+L2 -> 15 | P3: 2 | Q3: =Лист2!A3 -> 45544 | R3: =Лист2!B3 -> 2 | S3: =$M$2 -> 1.5887006 | T3: =$N$2*P3 -> 0.31986663 | U3: =S3+T3 -> 1.9085672 | V3: =IF(P3<=60,"Наблюдение","Упреждение") -> Наблюдение
A4: 4 | B4: =Лист2!B5 -> 1 | C4: =MAX(Лист2!$B$2:B4) -> 3 | D4: =MIN(Лист2!$B$2:B4) -> 1 | E4: =IF(B4>C4,1,0) -> 0 | F4: =IF(B4<D4,1,0) -> 0 | G4: =E4-F4 -> 0 | H4: =1/A4 -> 0.25 | I4: =A4+I3 -> 10 | J4: =A4^2+J3 -> 30 | K4: =B4+K3 -> 7 | L4: =A4*B4+L3 -> 19 | P4: 3 | Q4: =Лист2!A4 -> 45551 | R4: =Лист2!B4 -> 3 | S4: =$M$2 -> 1.5887006 | T4: =$N$2*P4 -> 0.47979994 | U4: =S4+T4 -> 2.0685005 | V4: =IF(P4<=60,"Наблюдение","Упреждение") -> Наблюдение
A5: 5 | B5: =Лист2!B6 -> 5 | C5: =MAX(Лист2!$B$2:B5) -> 3 | D5: =MIN(Лист2!$B$2:B5) -> 1 | E5: =IF(B5>C5,1,0) -> 1 | F5: =IF(B5<D5,1,0) -> 0 | G5: =E5-F5 -> 1 | H5: =1/A5 -> 0.2 | I5: =A5+I4 -> 15 | J5: =A5^2+J4 -> 55 | K5: =B5+K4 -> 12 | L5: =A5*B5+L4 -> 44 | P5: 4 | Q5: =Лист2!A5 -> 45565 | R5: =Лист2!B5 -> 1 | S5: =$M$2 -> 1.5887006 | T5: =$N$2*P5 -> 0.63973326 | U5: =S5+T5 -> 2.2284338 | V5: =IF(P5<=60,"Наблюдение","Упреждение") -> Наблюдение
A6: 6 | B6: =Лист2!B7 -> 5 | C6: =MAX(Лист2!$B$2:B6) -> 5 | D6: =MIN(Лист2!$B$2:B6) -> 1 | E6: =IF(B6>C6,1,0) -> 0 | F6: =IF(B6<D6,1,0) -> 0 | G6: =E6-F6 -> 0 | H6: =1/A6 -> 0.16666667 | I6: =A6+I5 -> 21 | J6: =A6^2+J5 -> 91 | K6: =B6+K5 -> 17 | L6: =A6*B6+L5 -> 74 | P6: 5 | Q6: =Лист2!A6 -> 45572 | R6: =Лист2!B6 -> 5 | S6: =$M$2 -> 1.5887006 | T6: =$N$2*P6 -> 0.79966657 | U6: =S6+T6 -> 2.3883671 | V6: =IF(P6<=60,"Наблюдение","Упреждение") -> Наблюдение
A7: 7 | B7: =Лист2!B8 -> 2 | C7: =MAX(Лист2!$B$2:B7) -> 5 | D7: =MIN(Лист2!$B$2:B7) -> 1 | E7: =IF(B7>C7,1,0) -> 0 | F7: =IF(B7<D7,1,0) -> 0 | G7: =E7-F7 -> 0 | H7: =1/A7 -> 0.14285714 | I7: =A7+I6 -> 28 | J7: =A7^2+J6 -> 140 | K7: =B7+K6 -> 19 | L7: =A7*B7+L6 -> 88 | P7: 6 | Q7: =Лист2!A7 -> 45579 | R7: =Лист2!B7 -> 5 | S7: =$M$2 -> 1.5887006 | T7: =$N$2*P7 -> 0.95959989 | U7: =S7+T7 -> 2.5483005 | V7: =IF(P7<=60,"Наблюдение","Упреждение") -> Наблюдение
A8: 8 | B8: =Лист2!B9 -> 2 | C8: =MAX(Лист2!$B$2:B8) -> 5 | D8: =MIN(Лист2!$B$2:B8) -> 1 | E8: =IF(B8>C8,1,0) -> 0 | F8: =IF(B8<D8,1,0) -> 0 | G8: =E8-F8 -> 0 | H8: =1/A8 -> 0.125 | I8: =A8+I7 -> 36 | J8: =A8^2+J7 -> 204 | K8: =B8+K7 -> 21 | L8: =A8*B8+L7 -> 104 | P8: 7 | Q8: =Лист2!A8 -> 45586 | R8: =Лист2!B8 -> 2 | S8: =$M$2 -> 1.5887006 | T8: =$N$2*P8 -> 1.1195332 | U8: =S8+T8 -> 2.7082338 | V8: =IF(P8<=60,"Наблюдение","Упреждение") -> Наблюдение
A9: 9 | B9: =Лист2!B10 -> 3 | C9: =MAX(Лист2!$B$2:B9) -> 5 | D9: =MIN(Лист2!$B$2:B9) -> 1 | E9: =IF(B9>C9,1,0) -> 0 | F9: =IF(B9<D9,1,0) -> 0 | G9: =E9-F9 -> 0 | H9: =1/A9 -> 0.11111111 | I9: =A9+I8 -> 45 | J9: =A9^2+J8 -> 285 | K9: =B9+K8 -> 24 | L9: =A9*B9+L8 -> 131 | P9: 8 | Q9: =Лист2!A9 -> 45593 | R9: =Лист2!B9 -> 2 | S9: =$M$2 -> 1.5887006 | T9: =$N$2*P9 -> 1.2794665 | U9: =S9+T9 -> 2.8681671 | V9: =IF(P9<=60,"Наблюдение","Упреждение") -> Наблюдение
A10: 10 | B10: =Лист2!B11 -> 5 | C10: =MAX(Лист2!$B$2:B10) -> 5 | D10: =MIN(Лист2!$B$2:B10) -> 1 | E10: =IF(B10>C10,1,0) -> 0 | F10: =IF(B10<D10,1,0) -> 0 | G10: =E10-F10 -> 0 | H10: =1/A10 -> 0.1 | I10: =A10+I9 -> 55 | J10: =A10^2+J9 -> 385 | K10: =B10+K9 -> 29 | L10: =A10*B10+L9 -> 181 | P10: 9 | Q10: =Лист2!A10 -> 45600 | R10: =Лист2!B10 -> 3 | S10: =$M$2 -> 1.5887006 | T10: =$N$2*P10 -> 1.4393998 | U10: =S10+T10 -> 3.0281004 | V10: =IF(P10<=60,"Наблюдение","Упреждение") -> Наблюдение
A11: 11 | B11: =Лист2!B12 -> 4 | C11: =MAX(Лист2!$B$2:B11) -> 5 | D11: =MIN(Лист2!$B$2:B11) -> 1 | E11: =IF(B11>C11,1,0) -> 0 | F11: =IF(B11<D11,1,0) -> 0 | G11: =E11-F11 -> 0 | H11: =1/A11 -> 0.090909091 | I11: =A11+I10 -> 66 | J11: =A11^2+J10 -> 506 | K11: =B11+K10 -> 33 | L11: =A11*B11+L10 -> 225 | P11: 10 | Q11: =Лист2!A11 -> 45607 | R11: =Лист2!B11 -> 5 | S11: =$M$2 -> 1.5887006 | T11: =$N$2*P11 -> 1.5993331 | U11: =S11+T11 -> 3.1880337 | V11: =IF(P11<=60,"Наблюдение","Упреждение") -> Наблюдение
A12: 12 | B12: =Лист2!B13 -> 4 | C12: =MAX(Лист2!$B$2:B12) -> 5 | D12: =MIN(Лист2!$B$2:B12) -> 1 | E12: =IF(B12>C12,1,0) -> 0 | F12: =IF(B12<D12,1,0) -> 0 | G12: =E12-F12 -> 0 | H12: =1/A12 -> 0.083333333 | I12: =A12+I11 -> 78 | J12: =A12^2+J11 -> 650 | K12: =B12+K11 -> 37 | L12: =A12*B12+L11 -> 273 | P12: 11 | Q12: =Лист2!A12 -> 45614 | R12: =Лист2!B12 -> 4 | S12: =$M$2 -> 1.5887006 | T12: =$N$2*P12 -> 1.7592665 | U12: =S12+T12 -> 3.347967 | V12: =IF(P12<=60,"Наблюдение","Упреждение") -> Наблюдение
A13: 13 | B13: =Лист2!B14 -> 2 | C13: =MAX(Лист2!$B$2:B13) -> 5 | D13: =MIN(Лист2!$B$2:B13) -> 1 | E13: =IF(B13>C13,1,0) -> 0 | F13: =IF(B13<D13,1,0) -> 0 | G13: =E13-F13 -> 0 | H13: =1/A13 -> 0.076923077 | I13: =A13+I12 -> 91 | J13: =A13^2+J12 -> 819 | K13: =B13+K12 -> 39 | L13: =A13*B13+L12 -> 299 | P13: 12 | Q13: =Лист2!A13 -> 45621 | R13: =Лист2!B13 -> 4 | S13: =$M$2 -> 1.5887006 | T13: =$N$2*P13 -> 1.9191998 | U13: =S13+T13 -> 3.5079003 | V13: =IF(P13<=60,"Наблюдение","Упреждение") -> Наблюдение
A14: 14 | B14: =Лист2!B15 -> 4 | C14: =MAX(Лист2!$B$2:B14) -> 5 | D14: =MIN(Лист2!$B$2:B14) -> 1 | E14: =IF(B14>C14,1,0) -> 0 | F14: =IF(B14<D14,1,0) -> 0 | G14: =E14-F14 -> 0 | H14: =1/A14 -> 0.071428571 | I14: =A14+I13 -> 105 | J14: =A14^2+J13 -> 1015 | K14: =B14+K13 -> 43 | L14: =A14*B14+L13 -> 355 | P14: 13 | Q14: =Лист2!A14 -> 45635 | R14: =Лист2!B14 -> 2 | S14: =$M$2 -> 1.5887006 | T14: =$N$2*P14 -> 2.0791331 | U14: =S14+T14 -> 3.6678337 | V14: =IF(P14<=60,"Наблюдение","Упреждение") -> Наблюдение
... A60: 60 | B60: =Лист2!B61 -> 2 | C60: =MAX(Лист2!$B$2:B60) -> 15 | D60: =MIN(Лист2!$B$2:B60) -> 1 | E60: =IF(B60>C60,1,0) -> 0 | F60: =IF(B60<D60,1,0) -> 0 | G60: =E60-F60 -> 0 | H60: =1/A60 -> 0.016666667 | I60: =A60+I59 -> 1830 | J60: =A60^2+J59 -> 73810 | K60: =B60+K59 -> 388 | L60: =A60*B60+L59 -> 14712 | P60: 59 | Q60: =Лист2!A60 -> 45964 | R60: =Лист2!B60 -> 9 | S60: =$M$2 -> 1.5887006 | T60: =$N$2*P60 -> 9.4360656 | U60: =S60+T60 -> 11.024766 | V60: =IF(P60<=60,"Наблюдение","Упреждение") -> Наблюдение
P61: 60 | Q61: =Лист2!A61 -> 45971 | R61: =Лист2!B61 -> 2 | S61: =$M$2 -> 1.5887006 | T61: =$N$2*P61 -> 9.5959989 | U61: =S61+T61 -> 11.184699 | V61: =IF(P61<=60,"Наблюдение","Упреждение") -> Наблюдение | W61: 0
P62: 61 | Q62: =Лист2!A62 -> 45978 | S62: =$M$2 -> 1.5887006 | T62: =$N$2*P62 -> 9.7559322 | U62: =S62+T62 -> 11.344633 | V62: =IF(P62<=60,"Наблюдение","Упреждение") -> Упреждение | W62: 20
P63: 62 | Q63: =Лист2!A63 -> 45985 | S63: =$M$2 -> 1.5887006 | T63: =$N$2*P63 -> 9.9158655 | U63: =S63+T63 -> 11.504566 | V63: =IF(P63<=60,"Наблюдение","Упреждение") -> Упреждение
P64: 63 | Q64: =Лист2!A64 -> 45992 | S64: =$M$2 -> 1.5887006 | T64: =$N$2*P64 -> 10.075799 | U64: =S64+T64 -> 11.664499 | V64: =IF(P64<=60,"Наблюдение","Упреждение") -> Упреждение
P65: 64 | Q65: =Лист2!A65 -> 45999 | S65: =$M$2 -> 1.5887006 | T65: =$N$2*P65 -> 10.235732 | U65: =S65+T65 -> 11.824433 | V65: =IF(P65<=60,"Наблюдение","Упреждение") -> Упреждение
P66: 65 | Q66: =Лист2!A66 -> 46006 | S66: =$M$2 -> 1.5887006 | T66: =$N$2*P66 -> 10.395665 | U66: =S66+T66 -> 11.984366 | V66: =IF(P66<=60,"Наблюдение","Упреждение") -> Упреждение
P67: 66 | Q67: =Лист2!A67 -> 46013 | S67: =$M$2 -> 1.5887006 | T67: =$N$2*P67 -> 10.555599 | U67: =S67+T67 -> 12.144299 | V67: =IF(P67<=60,"Наблюдение","Упреждение") -> Упреждение
P68: 67 | Q68: =Лист2!A68 -> 46020 | S68: =$M$2 -> 1.5887006 | T68: =$N$2*P68 -> 10.715532 | U68: =S68+T68 -> 12.304233 | V68: =IF(P68<=60,"Наблюдение","Упреждение") -> Упреждение
P69: 68 | Q69: =Лист2!A69 -> 46027 | S69: =$M$2 -> 1.5887006 | T69: =$N$2*P69 -> 10.875465 | U69: =S69+T69 -> 12.464166 | V69: =IF(P69<=60,"Наблюдение","Упреждение") -> Упреждение
P70: 69 | Q70: =Лист2!A70 -> 46034 | S70: =$M$2 -> 1.5887006 | T70: =$N$2*P70 -> 11.035399 | U70: =S70+T70 -> 12.624099 | V70: =IF(P70<=60,"Наблюдение","Упреждение") -> Упреждение
P71: 70 | Q71: =Лист2!A71 -> 46041 | S71: =$M$2 -> 1.5887006 | T71: =$N$2*P71 -> 11.195332 | U71: =S71+T71 -> 12.784033 | V71: =IF(P71<=60,"Наблюдение","Упреждение") -> Упреждение
P72: 71 | Q72: =Лист2!A72 -> 46048 | S72: =$M$2 -> 1.5887006 | T72: =$N$2*P72 -> 11.355265 | U72: =S72+T72 -> 12.943966 | V72: =IF(P72<=60,"Наблюдение","Упреждение") -> Упреждение
P73: 72 | Q73: =Лист2!A73 -> 46055 | S73: =$M$2 -> 1.5887006 | T73: =$N$2*P73 -> 11.515199 | U73: =S73+T73 -> 13.103899 | V73: =IF(P73<=60,"Наблюдение","Упреждение") -> Упреждение
P74: 73 | Q74: =Лист2!A74 -> 46062 | S74: =$M$2 -> 1.5887006 | T74: =$N$2*P74 -> 11.675132 | U74: =S74+T74 -> 13.263833 | V74: =IF(P74<=60,"Наблюдение","Упреждение") -> Упреждение
... P100: 99 | Q100: =Лист2!A100 -> 46244 | S100: =$M$2 -> 1.5887006 | T100: =$N$2*P100 -> 15.833398 | U100: =S100+T100 -> 17.422099 | V100: =IF(P100<=60,"Наблюдение","Упреждение") -> Упреждение

Sheet Прогноз 60 39
A1: Номер недели | B1: Дата недели | C1: Известное x_t | D1: Факт для проверки | E1: Линейный тренд / прогноз | F1: Прогноз округлённый | G1: Цепной прирост | H1: Базисный прирост к x_60 | I1: Накоплено инцидентов | J1: Накопленный прирост к x_60 | K1: Цепной темп роста, % | L1: Базисный темп роста, % | M1: Цепной темп прироста, % | N1: Базисный темп прироста, % | O1: Абсолютная ошибка | P1: Относительная ошибка, % | Q1: Квадрат ошибки | R1: sMAPE, % | S1: Учебный метод Δ̄ | T1: Накопленный итог с 1-й недели
A2: 1 | B2: =Лист2!A2 -> 45537 | C2: =Лист2!B2 -> 1 | E2: ='Итоги 60 39'!$B$6+'Итоги 60 39'!$B$5*A2 -> 1.7502732
A3: 2 | B3: =Лист2!A3 -> 45544 | C3: =Лист2!B3 -> 2 | E3: ='Итоги 60 39'!$B$6+'Итоги 60 39'!$B$5*A3 -> 1.910151
A4: 3 | B4: =Лист2!A4 -> 45551 | C4: =Лист2!B4 -> 3 | E4: ='Итоги 60 39'!$B$6+'Итоги 60 39'!$B$5*A4 -> 2.0700287
A5: 4 | B5: =Лист2!A5 -> 45565 | C5: =Лист2!B5 -> 1 | E5: ='Итоги 60 39'!$B$6+'Итоги 60 39'!$B$5*A5 -> 2.2299065
A6: 5 | B6: =Лист2!A6 -> 45572 | C6: =Лист2!B6 -> 5 | E6: ='Итоги 60 39'!$B$6+'Итоги 60 39'!$B$5*A6 -> 2.3897842
A7: 6 | B7: =Лист2!A7 -> 45579 | C7: =Лист2!B7 -> 5 | E7: ='Итоги 60 39'!$B$6+'Итоги 60 39'!$B$5*A7 -> 2.5496619
A8: 7 | B8: =Лист2!A8 -> 45586 | C8: =Лист2!B8 -> 2 | E8: ='Итоги 60 39'!$B$6+'Итоги 60 39'!$B$5*A8 -> 2.7095397
A9: 8 | B9: =Лист2!A9 -> 45593 | C9: =Лист2!B9 -> 2 | E9: ='Итоги 60 39'!$B$6+'Итоги 60 39'!$B$5*A9 -> 2.8694174
A10: 9 | B10: =Лист2!A10 -> 45600 | C10: =Лист2!B10 -> 3 | E10: ='Итоги 60 39'!$B$6+'Итоги 60 39'!$B$5*A10 -> 3.0292952
A11: 10 | B11: =Лист2!A11 -> 45607 | C11: =Лист2!B11 -> 5 | E11: ='Итоги 60 39'!$B$6+'Итоги 60 39'!$B$5*A11 -> 3.1891729
A12: 11 | B12: =Лист2!A12 -> 45614 | C12: =Лист2!B12 -> 4 | E12: ='Итоги 60 39'!$B$6+'Итоги 60 39'!$B$5*A12 -> 3.3490507
A13: 12 | B13: =Лист2!A13 -> 45621 | C13: =Лист2!B13 -> 4 | E13: ='Итоги 60 39'!$B$6+'Итоги 60 39'!$B$5*A13 -> 3.5089284
... A61: 60 | B61: =Лист2!A61 -> 45971 | C61: =Лист2!B61 -> 2 | E61: ='Итоги 60 39'!$B$6+'Итоги 60 39'!$B$5*A61 -> 11.18306
A62: 61 | B62: =Лист2!A62 -> 45978 | D62: =Лист2!B62 -> 22 | E62: ='Итоги 60 39'!$B$6+'Итоги 60 39'!$B$5*A62 -> 11.342938 | F62: =ROUND(E62,0) -> 11 | G62: =E62-$C$61 -> 9.3429379 | H62: =E62-$C$61 -> 9.3429379 | I62: =SUM($E$62:E62) -> 11.342938 | J62: =I62-(A62-60)*$C$61 -> 9.3429379 | K62: =E62/$C$61*100 -> 567.14689 | L62: =E62/$C$61*100 -> 567.14689 | M62: =K62-100 -> 467.14689 | N62: =L62-100 -> 467.14689 | O62: =ABS(D62-E62) -> 10.657062 | P62: =IF(D62=0,"",O62/D62*100) -> 48.441192 | Q62: =(D62-E62)^2 -> 113.57297 | R62: =IF(D62+E62=0,0,200*ABS(D62-E62)/(ABS(D62)+ABS(E62))) -> 63.923954 | S62: =$C$61+(A62-60)*'Итоги 60 39'!$B$22 -> 2.0169492 | T62: =SUM($C$2:$C$61)+I62 -> 399.34294
A63: 62 | B63: =Лист2!A63 -> 45985 | D63: =Лист2!B63 -> 21 | E63: ='Итоги 60 39'!$B$6+'Итоги 60 39'!$B$5*A63 -> 11.502816 | F63: =ROUND(E63,0) -> 12 | G63: =E63-E62 -> 0.15987774 | H63: =E63-$C$61 -> 9.5028156 | I63: =SUM($E$62:E63) -> 22.845753 | J63: =I63-(A63-60)*$C$61 -> 18.845753 | K63: =E63/E62*100 -> 101.40949 | L63: =E63/$C$61*100 -> 575.14078 | M63: =K63-100 -> 1.4094915 | N63: =L63-100 -> 475.14078 | O63: =ABS(D63-E63) -> 9.4971844 | P63: =IF(D63=0,"",O63/D63*100) -> 45.224688 | Q63: =(D63-E63)^2 -> 90.196512 | R63: =IF(D63+E63=0,0,200*ABS(D63-E63)/(ABS(D63)+ABS(E63))) -> 58.439149 | S63: =$C$61+(A63-60)*'Итоги 60 39'!$B$22 -> 2.0338983 | T63: =SUM($C$2:$C$61)+I63 -> 410.84575
A64: 63 | B64: =Лист2!A64 -> 45992 | D64: =Лист2!B64 -> 19 | E64: ='Итоги 60 39'!$B$6+'Итоги 60 39'!$B$5*A64 -> 11.662693 | F64: =ROUND(E64,0) -> 12 | G64: =E64-E63 -> 0.15987774 | H64: =E64-$C$61 -> 9.6626933 | I64: =SUM($E$62:E64) -> 34.508447 | J64: =I64-(A64-60)*$C$61 -> 28.508447 | K64: =E64/E63*100 -> 101.3899 | L64: =E64/$C$61*100 -> 583.13467 | M64: =K64-100 -> 1.389901 | N64: =L64-100 -> 483.13467 | O64: =ABS(D64-E64) -> 7.3373067 | P64: =IF(D64=0,"",O64/D64*100) -> 38.617403 | Q64: =(D64-E64)^2 -> 53.836069 | R64: =IF(D64+E64=0,0,200*ABS(D64-E64)/(ABS(D64)+ABS(E64))) -> 47.858201 | S64: =$C$61+(A64-60)*'Итоги 60 39'!$B$22 -> 2.0508475 | T64: =SUM($C$2:$C$61)+I64 -> 422.50845
A65: 64 | B65: =Лист2!A65 -> 45999 | D65: =Лист2!B65 -> 21 | E65: ='Итоги 60 39'!$B$6+'Итоги 60 39'!$B$5*A65 -> 11.822571 | F65: =ROUND(E65,0) -> 12 | G65: =E65-E64 -> 0.15987774 | H65: =E65-$C$61 -> 9.8225711 | I65: =SUM($E$62:E65) -> 46.331018 | J65: =I65-(A65-60)*$C$61 -> 38.331018 | K65: =E65/E64*100 -> 101.37085 | L65: =E65/$C$61*100 -> 591.12855 | M65: =K65-100 -> 1.3708475 | N65: =L65-100 -> 491.12855 | O65: =ABS(D65-E65) -> 9.1774289 | P65: =IF(D65=0,"",O65/D65*100) -> 43.702042 | Q65: =(D65-E65)^2 -> 84.225201 | R65: =IF(D65+E65=0,0,200*ABS(D65-E65)/(ABS(D65)+ABS(E65))) -> 55.92145 | S65: =$C$61+(A65-60)*'Итоги 60 39'!$B$22 -> 2.0677966 | T65: =SUM($C$2:$C$61)+I65 -> 434.33102
A66: 65 | B66: =Лист2!A66 -> 46006 | D66: =Лист2!B66 -> 10 | E66: ='Итоги 60 39'!$B$6+'Итоги 60 39'!$B$5*A66 -> 11.982449 | F66: =ROUND(E66,0) -> 12 | G66: =E66-E65 -> 0.15987774 | H66: =E66-$C$61 -> 9.9824488 | I66: =SUM($E$62:E66) -> 58.313467 | J66: =I66-(A66-60)*$C$61 -> 48.313467 | K66: =E66/E65*100 -> 101.35231 | L66: =E66/$C$61*100 -> 599.12244 | M66: =K66-100 -> 1.3523094 | N66: =L66-100 -> 499.12244 | O66: =ABS(D66-E66) -> 1.9824488 | P66: =IF(D66=0,"",O66/D66*100) -> 19.824488 | Q66: =(D66-E66)^2 -> 3.9301034 | R66: =IF(D66+E66=0,0,200*ABS(D66-E66)/(ABS(D66)+ABS(E66))) -> 18.036651 | S66: =$C$61+(A66-60)*'Итоги 60 39'!$B$22 -> 2.0847458 | T66: =SUM($C$2:$C$61)+I66 -> 446.31347
A67: 66 | B67: =Лист2!A67 -> 46013 | D67: =Лист2!B67 -> 7 | E67: ='Итоги 60 39'!$B$6+'Итоги 60 39'!$B$5*A67 -> 12.142327 | F67: =ROUND(E67,0) -> 12 | G67: =E67-E66 -> 0.15987774 | H67: =E67-$C$61 -> 10.142327 | I67: =SUM($E$62:E67) -> 70.455793 | J67: =I67-(A67-60)*$C$61 -> 58.455793 | K67: =E67/E66*100 -> 101.33427 | L67: =E67/$C$61*100 -> 607.11633 | M67: =K67-100 -> 1.334266 | N67: =L67-100 -> 507.11633 | O67: =ABS(D67-E67) -> 5.1423266 | P67: =IF(D67=0,"",O67/D67*100) -> 73.461808 | Q67: =(D67-E67)^2 -> 26.443523 | R67: =IF(D67+E67=0,0,200*ABS(D67-E67)/(ABS(D67)+ABS(E67))) -> 53.727289 | S67: =$C$61+(A67-60)*'Итоги 60 39'!$B$22 -> 2.1016949 | T67: =SUM($C$2:$C$61)+I67 -> 458.45579
A68: 67 | B68: =Лист2!A68 -> 46020 | D68: =Лист2!B68 -> 11 | E68: ='Итоги 60 39'!$B$6+'Итоги 60 39'!$B$5*A68 -> 12.302204 | F68: =ROUND(E68,0) -> 12 | G68: =E68-E67 -> 0.15987774 | H68: =E68-$C$61 -> 10.302204 | I68: =SUM($E$62:E68) -> 82.757998 | J68: =I68-(A68-60)*$C$61 -> 68.757998 | K68: =E68/E67*100 -> 101.3167 | L68: =E68/$C$61*100 -> 615.11022 | M68: =K68-100 -> 1.3166978 | N68: =L68-100 -> 515.11022 | O68: =ABS(D68-E68) -> 1.3022043 | P68: =IF(D68=0,"",O68/D68*100) -> 11.838221 | Q68: =(D68-E68)^2 -> 1.6957361 | R68: =IF(D68+E68=0,0,200*ABS(D68-E68)/(ABS(D68)+ABS(E68))) -> 11.176662 | S68: =$C$61+(A68-60)*'Итоги 60 39'!$B$22 -> 2.1186441 | T68: =SUM($C$2:$C$61)+I68 -> 470.758
A69: 68 | B69: =Лист2!A69 -> 46027 | D69: =Лист2!B69 -> 21 | E69: ='Итоги 60 39'!$B$6+'Итоги 60 39'!$B$5*A69 -> 12.462082 | F69: =ROUND(E69,0) -> 12 | G69: =E69-E68 -> 0.15987774 | H69: =E69-$C$61 -> 10.462082 | I69: =SUM($E$62:E69) -> 95.22008 | J69: =I69-(A69-60)*$C$61 -> 79.22008 | K69: =E69/E68*100 -> 101.29959 | L69: =E69/$C$61*100 -> 623.1041 | M69: =K69-100 -> 1.2995862 | N69: =L69-100 -> 523.1041 | O69: =ABS(D69-E69) -> 8.5379179 | P69: =IF(D69=0,"",O69/D69*100) -> 40.656752 | Q69: =(D69-E69)^2 -> 72.896043 | R69: =IF(D69+E69=0,0,200*ABS(D69-E69)/(ABS(D69)+ABS(E69))) -> 51.030405 | S69: =$C$61+(A69-60)*'Итоги 60 39'!$B$22 -> 2.1355932 | T69: =SUM($C$2:$C$61)+I69 -> 483.22008
A70: 69 | B70: =Лист2!A70 -> 46034 | D70: =Лист2!B70 -> 15 | E70: ='Итоги 60 39'!$B$6+'Итоги 60 39'!$B$5*A70 -> 12.62196 | F70: =ROUND(E70,0) -> 13 | G70: =E70-E69 -> 0.15987774 | H70: =E70-$C$61 -> 10.62196 | I70: =SUM($E$62:E70) -> 107.84204 | J70: =I70-(A70-60)*$C$61 -> 89.842039 | K70: =E70/E69*100 -> 101.28291 | L70: =E70/$C$61*100 -> 631.09799 | M70: =K70-100 -> 1.2829136 | N70: =L70-100 -> 531.09799 | O70: =ABS(D70-E70) -> 2.3780402 | P70: =IF(D70=0,"",O70/D70*100) -> 15.853601 | Q70: =(D70-E70)^2 -> 5.6550752 | R70: =IF(D70+E70=0,0,200*ABS(D70-E70)/(ABS(D70)+ABS(E70))) -> 17.218476 | S70: =$C$61+(A70-60)*'Итоги 60 39'!$B$22 -> 2.1525424 | T70: =SUM($C$2:$C$61)+I70 -> 495.84204
A71: 70 | B71: =Лист2!A71 -> 46041 | D71: =Лист2!B71 -> 9 | E71: ='Итоги 60 39'!$B$6+'Итоги 60 39'!$B$5*A71 -> 12.781838 | F71: =ROUND(E71,0) -> 13 | G71: =E71-E70 -> 0.15987774 | H71: =E71-$C$61 -> 10.781838 | I71: =SUM($E$62:E71) -> 120.62388 | J71: =I71-(A71-60)*$C$61 -> 100.62388 | K71: =E71/E70*100 -> 101.26666 | L71: =E71/$C$61*100 -> 639.09188 | M71: =K71-100 -> 1.2666634 | N71: =L71-100 -> 539.09188 | O71: =ABS(D71-E71) -> 3.7818375 | P71: =IF(D71=0,"",O71/D71*100) -> 42.020417 | Q71: =(D71-E71)^2 -> 14.302295 | R71: =IF(D71+E71=0,0,200*ABS(D71-E71)/(ABS(D71)+ABS(E71))) -> 34.724688 | S71: =$C$61+(A71-60)*'Итоги 60 39'!$B$22 -> 2.1694915 | T71: =SUM($C$2:$C$61)+I71 -> 508.62388
A72: 71 | B72: =Лист2!A72 -> 46048 | D72: =Лист2!B72 -> 10 | E72: ='Итоги 60 39'!$B$6+'Итоги 60 39'!$B$5*A72 -> 12.941715 | F72: =ROUND(E72,0) -> 13 | G72: =E72-E71 -> 0.15987774 | H72: =E72-$C$61 -> 10.941715 | I72: =SUM($E$62:E72) -> 133.56559 | J72: =I72-(A72-60)*$C$61 -> 111.56559 | K72: =E72/E71*100 -> 101.25082 | L72: =E72/$C$61*100 -> 647.08576 | M72: =K72-100 -> 1.2508197 | N72: =L72-100 -> 547.08576 | O72: =ABS(D72-E72) -> 2.9417153 | P72: =IF(D72=0,"",O72/D72*100) -> 29.417153 | Q72: =(D72-E72)^2 -> 8.6536889 | R72: =IF(D72+E72=0,0,200*ABS(D72-E72)/(ABS(D72)+ABS(E72))) -> 25.645121 | S72: =$C$61+(A72-60)*'Итоги 60 39'!$B$22 -> 2.1864407 | T72: =SUM($C$2:$C$61)+I72 -> 521.56559
A73: 72 | B73: =Лист2!A73 -> 46055 | D73: =Лист2!B73 -> 15 | E73: ='Итоги 60 39'!$B$6+'Итоги 60 39'!$B$5*A73 -> 13.101593 | F73: =ROUND(E73,0) -> 13 | G73: =E73-E72 -> 0.15987774 | H73: =E73-$C$61 -> 11.101593 | I73: =SUM($E$62:E73) -> 146.66719 | J73: =I73-(A73-60)*$C$61 -> 122.66719 | K73: =E73/E72*100 -> 101.23537 | L73: =E73/$C$61*100 -> 655.07965 | M73: =K73-100 -> 1.2353675 | N73: =L73-100 -> 555.07965 | O73: =ABS(D73-E73) -> 1.898407 | P73: =IF(D73=0,"",O73/D73*100) -> 12.656046 | Q73: =(D73-E73)^2 -> 3.603949 | R73: =IF(D73+E73=0,0,200*ABS(D73-E73)/(ABS(D73)+ABS(E73))) -> 13.511027 | S73: =$C$61+(A73-60)*'Итоги 60 39'!$B$22 -> 2.2033898 | T73: =SUM($C$2:$C$61)+I73 -> 534.66719
A74: 73 | B74: =Лист2!A74 -> 46062 | D74: =Лист2!B74 -> 20 | E74: ='Итоги 60 39'!$B$6+'Итоги 60 39'!$B$5*A74 -> 13.261471 | F74: =ROUND(E74,0) -> 13 | G74: =E74-E73 -> 0.15987774 | H74: =E74-$C$61 -> 11.261471 | I74: =SUM($E$62:E74) -> 159.92866 | J74: =I74-(A74-60)*$C$61 -> 133.92866 | K74: =E74/E73*100 -> 101.22029 | L74: =E74/$C$61*100 -> 663.07354 | M74: =K74-100 -> 1.2202924 | N74: =L74-100 -> 563.07354 | O74: =ABS(D74-E74) -> 6.7385292 | P74: =IF(D74=0,"",O74/D74*100) -> 33.692646 | Q74: =(D74-E74)^2 -> 45.407776 | R74: =IF(D74+E74=0,0,200*ABS(D74-E74)/(ABS(D74)+ABS(E74))) -> 40.518528 | S74: =$C$61+(A74-60)*'Итоги 60 39'!$B$22 -> 2.220339 | T74: =SUM($C$2:$C$61)+I74 -> 547.92866
... A100: 99 | B100: =Лист2!A100 -> 46244 | D100: =Лист2!B100 -> 5 | E100: ='Итоги 60 39'!$B$6+'Итоги 60 39'!$B$5*A100 -> 17.418292 | F100: =ROUND(E100,0) -> 17 | G100: =E100-E99 -> 0.15987774 | H100: =E100-$C$61 -> 15.418292 | I100: =SUM($E$62:E100) -> 560.84398 | J100: =I100-(A100-60)*$C$61 -> 482.84398 | K100: =E100/E99*100 -> 100.92638 | L100: =E100/$C$61*100 -> 870.91461 | M100: =K100-100 -> 0.92637562 | N100: =L100-100 -> 770.91461 | O100: =ABS(D100-E100) -> 12.418292 | P100: =IF(D100=0,"",O100/D100*100) -> 248.36584 | Q100: =(D100-E100)^2 -> 154.21398 | R100: =IF(D100+E100=0,0,200*ABS(D100-E100)/(ABS(D100)+ABS(E100))) -> 110.78714 | S100: =$C$61+(A100-60)*'Итоги 60 39'!$B$22 -> 2.6610169 | T100: =SUM($C$2:$C$61)+I100 -> 948.84398

Sheet Итоги 60 39
A1: Показатель | B1: Значение
A2: Известных недель | B2: 60
A3: Проверочных недель | B3: 39
A4: Уровень доверия | B4: 0.96
A5: Наклон линейного тренда | B5: =SLOPE('Прогноз 60 39'!C2:C61,'Прогноз 60 39'!A2:A61) -> 0.15987774
A6: Свободный член | B6: =INTERCEPT('Прогноз 60 39'!C2:C61,'Прогноз 60 39'!A2:A61) -> 1.5903955
A7: Верхних рекордов U | B7: =SUM('Фостер Стюарт'!E2:E60) -> 9
A8: Нижних рекордов L | B8: =SUM('Фостер Стюарт'!F2:F60) -> 0
A9: D = U-L | B9: =B7-B8 -> 9
A10: Стандартная ошибка D | B10: =SQRT(2*SUM('Фостер Стюарт'!H2:H60)) -> 2.7128842
A11: Статистика Z | B11: =B9/B10 -> 3.3175024
A12: Критическое значение Z | B12: =_xlfn.NORM.S.INV((1+B4)/2) -> 2.0537489
A13: Двусторонний p-value | B13: =2*(1-_xlfn.NORM.S.DIST(ABS(B11),TRUE)) -> 0.00090826127
A14: Вывод о тренде | B14: =IF(ABS(B11)>B12,"Нулевая гипотеза отклонена: тренд есть","Нет оснований отвергнуть отсутствие тренда") -> Нулевая гипотеза отклонена: тренд есть
A15: Сумма прогноза 61–99 | B15: =SUM('Прогноз 60 39'!E62:E100) -> 560.84398
A16: Сумма факта 61–99 | B16: =SUM('Прогноз 60 39'!D62:D100) -> 654
A17: MAE | B17: =AVERAGE('Прогноз 60 39'!O62:O100) -> 5.3939786
A18: RMSE | B18: =SQRT(AVERAGE('Прогноз 60 39'!Q62:Q100)) -> 6.9602564
A19: WAPE, % | B19: =SUM('Прогноз 60 39'!O62:O100)/B16*100 -> 32.165928
A20: sMAPE, % | B20: =AVERAGE('Прогноз 60 39'!R62:R100) -> 33.481784
A21: Смещение прогноза | B21: =AVERAGE('Прогноз 60 39'!E62:E100)-AVERAGE('Прогноз 60 39'!D62:D100) -> -2.3886158
A22: Средний абсолютный прирост 1–60 | B22: =('Прогноз 60 39'!C61-'Прогноз 60 39'!C2)/(B2-1) -> 0.016949153
A23: Прогноз на неделю 61 | B23: ='Прогноз 60 39'!E62 -> 11.342938
A24: Прогноз на неделю 99 | B24: ='Прогноз 60 39'!E100 -> 17.418292

Sheet Прирост цепной и абсолютный 
A1: Номер t | B1: Дата недели | C1: Факт 1–60 | D1: Цепной абсолютный прирост | E1: Средний абсолютный прирост | F1: Прогноз без округления | G1: Прогноз, инциденты | H1: Факт 61–99 для проверки | I1: Абсолютная ошибка | J1: Относительная ошибка, %
A2: 1 | B2: =Лист2!A2 -> 45537 | C2: =Лист2!B2 -> 1 | L2: Показатель | M2: Значение
A3: 2 | B3: =Лист2!A3 -> 45544 | C3: =Лист2!B3 -> 2 | D3: =C3-C2 -> 1 | E3: =$M$6 -> 0.016949153 | L3: Обучающих наблюдений n | M3: =COUNT(C2:C61) -> 60
A4: 3 | B4: =Лист2!A4 -> 45551 | C4: =Лист2!B4 -> 3 | D4: =C4-C3 -> 1 | E4: =$M$6 -> 0.016949153 | L4: Первое значение y₁ | M4: =C2 -> 1
A5: 4 | B5: =Лист2!A5 -> 45565 | C5: =Лист2!B5 -> 1 | D5: =C5-C4 -> -2 | E5: =$M$6 -> 0.016949153 | L5: Последнее значение y₆₀ | M5: =C61 -> 2
A6: 5 | B6: =Лист2!A6 -> 45572 | C6: =Лист2!B6 -> 5 | D6: =C6-C5 -> 4 | E6: =$M$6 -> 0.016949153 | L6: Средний абсолютный прирост Δ̄ | M6: =(M5-M4)/(M3-1) -> 0.016949153
A7: 6 | B7: =Лист2!A7 -> 45579 | C7: =Лист2!B7 -> 5 | D7: =C7-C6 -> 0 | E7: =$M$6 -> 0.016949153 | L7: СКО цепных приростов | M7: =STDEV(D3:D61) -> 3.2456418
A8: 7 | B8: =Лист2!A8 -> 45586 | C8: =Лист2!B8 -> 2 | D8: =C8-C7 -> -3 | E8: =$M$6 -> 0.016949153 | L8: Минимальный прирост | M8: =MIN(D3:D61) -> -7
A9: 8 | B9: =Лист2!A9 -> 45593 | C9: =Лист2!B9 -> 2 | D9: =C9-C8 -> 0 | E9: =$M$6 -> 0.016949153 | L9: Максимальный прирост | M9: =MAX(D3:D61) -> 6
A10: 9 | B10: =Лист2!A10 -> 45600 | C10: =Лист2!B10 -> 3 | D10: =C10-C9 -> 1 | E10: =$M$6 -> 0.016949153 | L10: Прогноз на t=61, без округления | M10: =F62 -> 2.0169492
A11: 10 | B11: =Лист2!A11 -> 45607 | C11: =Лист2!B11 -> 5 | D11: =C11-C10 -> 2 | E11: =$M$6 -> 0.016949153 | L11: Прогноз на t=99, без округления | M11: =F100 -> 2.6610169
A12: 11 | B12: =Лист2!A12 -> 45614 | C12: =Лист2!B12 -> 4 | D12: =C12-C11 -> -1 | E12: =$M$6 -> 0.016949153 | L12: MAE по 39 контрольным строкам | M12: =AVERAGE(I62:I100) -> 14.512821
A13: 12 | B13: =Лист2!A13 -> 45621 | C13: =Лист2!B13 -> 4 | D13: =C13-C12 -> 0 | E13: =$M$6 -> 0.016949153 | L13: WAPE по 39 контрольным строкам, % | M13: =SUM(I62:I100)/SUM(H62:H100)*100 -> 86.544343
A14: 13 | B14: =Лист2!A14 -> 45635 | C14: =Лист2!B14 -> 2 | D14: =C14-C13 -> -2 | E14: =$M$6 -> 0.016949153 | L14: Среднее y₁…y₂₀ | M14: =AVERAGE(C2:C21) -> 3.15
A15: 14 | B15: =Лист2!A15 -> 45642 | C15: =Лист2!B15 -> 4 | D15: =C15-C14 -> 2 | E15: =$M$6 -> 0.016949153 | L15: Среднее y₂₁…y₄₀ | M15: =AVERAGE(C22:C41) -> 6.55
A16: 15 | B16: =Лист2!A16 -> 45649 | C16: =Лист2!B16 -> 2 | D16: =C16-C15 -> -2 | E16: =$M$6 -> 0.016949153 | L16: Среднее y₄₁…y₆₀ | M16: =AVERAGE(C42:C61) -> 9.7
A17: 16 | B17: =Лист2!A17 -> 45656 | C17: =Лист2!B17 -> 5 | D17: =C17-C16 -> 3 | E17: =$M$6 -> 0.016949153
A18: 17 | B18: =Лист2!A18 -> 45663 | C18: =Лист2!B18 -> 2 | D18: =C18-C17 -> -3 | E18: =$M$6 -> 0.016949153 | L18: Формула: ŷ₆₀₊ₕ = y₆₀ + h·Δ̄, где h=1…39.
A19: 18 | B19: =Лист2!A19 -> 45670 | C19: =Лист2!B19 -> 4 | D19: =C19-C18 -> 2 | E19: =$M$6 -> 0.016949153 | L19: Контрольные факты не участвуют в расчёте Δ̄ и прогноза.
A20: 19 | B20: =Лист2!A20 -> 45677 | C20: =Лист2!B20 -> 3 | D20: =C20-C19 -> -1 | E20: =$M$6 -> 0.016949153 | L20: Ограничение: низкое y₆₀ делает средний прирост близким к нулю.
A21: 20 | B21: =Лист2!A21 -> 45684 | C21: =Лист2!B21 -> 4 | D21: =C21-C20 -> 1 | E21: =$M$6 -> 0.016949153
A22: 21 | B22: =Лист2!A22 -> 45691 | C22: =Лист2!B22 -> 1 | D22: =C22-C21 -> -3 | E22: =$M$6 -> 0.016949153
A23: 22 | B23: =Лист2!A23 -> 45698 | C23: =Лист2!B23 -> 7 | D23: =C23-C22 -> 6 | E23: =$M$6 -> 0.016949153
A24: 23 | B24: =Лист2!A24 -> 45712 | C24: =Лист2!B24 -> 8 | D24: =C24-C23 -> 1 | E24: =$M$6 -> 0.016949153
A25: 24 | B25: =Лист2!A25 -> 45719 | C25: =Лист2!B25 -> 4 | D25: =C25-C24 -> -4 | E25: =$M$6 -> 0.016949153
A26: 25 | B26: =Лист2!A26 -> 45726 | C26: =Лист2!B26 -> 4 | D26: =C26-C25 -> 0 | E26: =$M$6 -> 0.016949153
A27: 26 | B27: =Лист2!A27 -> 45733 | C27: =Лист2!B27 -> 8 | D27: =C27-C26 -> 4 | E27: =$M$6 -> 0.016949153
A28: 27 | B28: =Лист2!A28 -> 45740 | C28: =Лист2!B28 -> 5 | D28: =C28-C27 -> -3 | E28: =$M$6 -> 0.016949153
A29: 28 | B29: =Лист2!A29 -> 45747 | C29: =Лист2!B29 -> 8 | D29: =C29-C28 -> 3 | E29: =$M$6 -> 0.016949153
A30: 29 | B30: =Лист2!A30 -> 45754 | C30: =Лист2!B30 -> 7 | D30: =C30-C29 -> -1 | E30: =$M$6 -> 0.016949153
A31: 30 | B31: =Лист2!A31 -> 45761 | C31: =Лист2!B31 -> 2 | D31: =C31-C30 -> -5 | E31: =$M$6 -> 0.016949153
A32: 31 | B32: =Лист2!A32 -> 45768 | C32: =Лист2!B32 -> 7 | D32: =C32-C31 -> 5 | E32: =$M$6 -> 0.016949153
... A60: 59 | B60: =Лист2!A60 -> 45964 | C60: =Лист2!B60 -> 9 | D60: =C60-C59 -> -4 | E60: =$M$6 -> 0.016949153
A61: 60 | B61: =Лист2!A61 -> 45971 | C61: =Лист2!B61 -> 2 | D61: =C61-C60 -> -7 | E61: =$M$6 -> 0.016949153 | F61: =C61 -> 2 | G61: =C61 -> 2
A62: 61 | B62: =B61+7 -> 45978 | E62: =$M$6 -> 0.016949153 | F62: =$M$5+(A62-$M$3)*$M$6 -> 2.0169492 | G62: =ROUND(F62,0) -> 2 | H62: =Лист2!B62 -> 22 | I62: =ABS(H62-G62) -> 20 | J62: =IF(H62=0,"",I62/H62*100) -> 90.909091
A63: 62 | B63: =B62+7 -> 45985 | E63: =$M$6 -> 0.016949153 | F63: =$M$5+(A63-$M$3)*$M$6 -> 2.0338983 | G63: =ROUND(F63,0) -> 2 | H63: =Лист2!B63 -> 21 | I63: =ABS(H63-G63) -> 19 | J63: =IF(H63=0,"",I63/H63*100) -> 90.47619
A64: 63 | B64: =B63+7 -> 45992 | E64: =$M$6 -> 0.016949153 | F64: =$M$5+(A64-$M$3)*$M$6 -> 2.0508475 | G64: =ROUND(F64,0) -> 2 | H64: =Лист2!B64 -> 19 | I64: =ABS(H64-G64) -> 17 | J64: =IF(H64=0,"",I64/H64*100) -> 89.473684
A65: 64 | B65: =B64+7 -> 45999 | E65: =$M$6 -> 0.016949153 | F65: =$M$5+(A65-$M$3)*$M$6 -> 2.0677966 | G65: =ROUND(F65,0) -> 2 | H65: =Лист2!B65 -> 21 | I65: =ABS(H65-G65) -> 19 | J65: =IF(H65=0,"",I65/H65*100) -> 90.47619
A66: 65 | B66: =B65+7 -> 46006 | E66: =$M$6 -> 0.016949153 | F66: =$M$5+(A66-$M$3)*$M$6 -> 2.0847458 | G66: =ROUND(F66,0) -> 2 | H66: =Лист2!B66 -> 10 | I66: =ABS(H66-G66) -> 8 | J66: =IF(H66=0,"",I66/H66*100) -> 80
A67: 66 | B67: =B66+7 -> 46013 | E67: =$M$6 -> 0.016949153 | F67: =$M$5+(A67-$M$3)*$M$6 -> 2.1016949 | G67: =ROUND(F67,0) -> 2 | H67: =Лист2!B67 -> 7 | I67: =ABS(H67-G67) -> 5 | J67: =IF(H67=0,"",I67/H67*100) -> 71.428571
...
